Workbook

Sheet C++ viti III
A1: 1 | B1: 2 | C1: 3 | D1: 3 | E1: 3 | F1: 6 | G1: 7 | H1: 8 | I1: 9 | J1: 10 | K1: 11 | L1: 12 | M1: 13 | N1: 14 | O1: 15 | P1: 16
A2: Nr | B2: Tema | C2: Detyra Shtepie | D2: Fq Ditari | E2: Situata e të nxënit: | F2: Metodologjia dhe veprimtaritë e nxënësve: | G2: Vlerësimi: | H2: Burimet: | I2: Rezultatet e të nxënit sipas kompetencave kyç: | J2: Fjalët kyç: | K2: Lidhja me fusha të tjera ose me temat ndërkurrikulare: | L2: Nr | M2: Tema | N2: Organizimi i orës së mësimit: | O2: Detyre shtepie: | P2: Kompetencat që përfitojnë: | Q2: Java
A3: 1 | B3: Lenda1 Tema1 | C3: Detyre shtepie 1 | D3: faqe 1 | E3: Situata 1 | F3: Metodologjia 1 | G3: Vleresimi 1 | H3: Burimi 1 | I3: Rezultati 1 | J3: Fjale Kyce 1 | K3: Lidhja me fushat e tjera 1 | L3: =A3 -> 1 | M3: =B3 -> Lenda1 Tema1 | N3: Organizimi 1 | O3: Detyre shtepie 1: | P3: Kompetenca 1 | Q3: 1
A4: 2 | B4: Lenda1 Tema2 | C4: Detyre shtepie 2 | D4: faqe 2 | E4: Situata 2 | F4: Metodologjia 2 | G4: Vleresimi 2 | H4: Burimi 2 | I4: Rezultati 2 | J4: Fjale Kyce 2 | K4: Lidhja me fushat e tjera 2 | L4: =A4 -> 2 | M4: =B4 -> Lenda1 Tema2 | N4: Organizimi 2 | O4: Detyre shtepie 1: | P4: Kompetenca 2
A5: 3 | B5: Lenda1 Tema3 | C5: Detyre shtepie 3 | D5: faqe 3 | E5: Situata 3 | F5: Metodologjia 3 | G5: Vleresimi 3 | H5: Burimi 3 | I5: Rezultati 3 | J5: Fjale Kyce 3 | K5: Lidhja me fushat e tjera 3 | L5: =A5 -> 3 | M5: =B5 -> Lenda1 Tema3 | N5: Organizimi 3 | O5: Detyre shtepie 1: | P5: Kompetenca 3
A6: 4 | B6: Lenda1 Tema4 | C6: Detyre shtepie 4 | D6: faqe 4 | E6: Situata 4 | F6: Metodologjia 4 | G6: Vleresimi 4 | H6: Burimi 4 | I6: Rezultati 4 | J6: Fjale Kyce 4 | K6: Lidhja me fushat e tjera 4 | L6: =A6 -> 4 | M6: =B6 -> Lenda1 Tema4 | N6: Organizimi 4 | O6: Detyre shtepie 1: | P6: Kompetenca 4 | Q6: 2
A7: 5 | B7: Lenda1 Tema5 | C7: Detyre shtepie 5 | D7: faqe 5 | E7: Situata 5 | F7: Metodologjia 5 | G7: Vleresimi 5 | H7: Burimi 5 | I7: Rezultati 5 | J7: Fjale Kyce 5 | K7: Lidhja me fushat e tjera 5 | L7: =A7 -> 5 | M7: =B7 -> Lenda1 Tema5 | N7: Organizimi 5 | O7: Detyre shtepie 1: | P7: Kompetenca 5
A8: 6 | B8: Lenda1 Tema6 | C8: Detyre shtepie 6 | D8: faqe 6 | E8: Situata 6 | F8: Metodologjia 6 | G8: Vleresimi 6 | H8: Burimi 6 | I8: Rezultati 6 | J8: Fjale Kyce 6 | K8: Lidhja me fushat e tjera 6 | L8: =A8 -> 6 | M8: =B8 -> Lenda1 Tema6 | N8: Organizimi 6 | O8: Detyre shtepie 1: | P8: Kompetenca 6
A9: 7 | B9: Lenda1 Tema7 | C9: Detyre shtepie 7 | D9: faqe 7 | E9: Situata 7 | F9: Metodologjia 7 | G9: Vleresimi 7 | H9: Burimi 7 | I9: Rezultati 7 | J9: Fjale Kyce 7 | K9: Lidhja me fushat e tjera 7 | L9: =A9 -> 7 | M9: =B9 -> Lenda1 Tema7 | N9: Organizimi 7 | O9: Detyre shtepie 1: | P9: Kompetenca 7 | Q9: 3
A10: 8 | B10: Lenda1 Tema8 | C10: Detyre shtepie 8 | D10: faqe 8 | E10: Situata 8 | F10: Metodologjia 8 | G10: Vleresimi 8 | H10: Burimi 8 | I10: Rezultati 8 | J10: Fjale Kyce 8 | K10: Lidhja me fushat e tjera 8 | L10: =A10 -> 8 | M10: =B10 -> Lenda1 Tema8 | N10: Organizimi 8 | O10: Detyre shtepie 1: | P10: Kompetenca 8
A11: 9 | B11: Lenda1 Tema9 | C11: Detyre shtepie 9 | D11: faqe 9 | E11: Situata 9 | F11: Metodologjia 9 | G11: Vleresimi 9 | H11: Burimi 9 | I11: Rezultati 9 | J11: Fjale Kyce 9 | K11: Lidhja me fushat e tjera 9 | L11: =A11 -> 9 | M11: =B11 -> Lenda1 Tema9 | N11: Organizimi 9 | O11: Detyre shtepie 1: | P11: Kompetenca 9
A12: 10 | B12: Lenda1 Tema10 | C12: Detyre shtepie 10 | D12: faqe 10 | E12: Situata 10 | F12: Metodologjia 10 | G12: Vleresimi 10 | H12: Burimi 10 | I12: Rezultati 10 | J12: Fjale Kyce 10 | K12: Lidhja me fushat e tjera 10 | L12: =A12 -> 10 | M12: =B12 -> Lenda1 Tema10 | N12: Organizimi 10 | O12: Detyre shtepie 1: | P12: Kompetenca 10 | Q12: 4
A13: 11 | B13: Lenda1 Tema11 | C13: Detyre shtepie 11 | D13: faqe 11 | E13: Situata 11 | F13: Metodologjia 11 | G13: Vleresimi 11 | H13: Burimi 11 | I13: Rezultati 11 | J13: Fjale Kyce 11 | K13: Lidhja me fushat e tjera 11 | L13: =A13 -> 11 | M13: =B13 -> Lenda1 Tema11 | N13: Organizimi 11 | O13: Detyre shtepie 1: | P13: Kompetenca 11
A14: 12 | B14: Lenda1 Tema12 | C14: Detyre shtepie 12 | D14: faqe 12 | E14: Situata 12 | F14: Metodologjia 12 | G14: Vleresimi 12 | H14: Burimi 12 | I14: Rezultati 12 | J14: Fjale Kyce 12 | K14: Lidhja me fushat e tjera 12 | L14: =A14 -> 12 | M14: =B14 -> Lenda1 Tema12 | N14: Organizimi 12 | O14: Detyre shtepie 1: | P14: Kompetenca 12
A15: 13 | B15: Lenda1 Tema13 | C15: Detyre shtepie 13 | D15: faqe 13 | E15: Situata 13 | F15: Metodologjia 13 | G15: Vleresimi 13 | H15: Burimi 13 | I15: Rezultati 13 | J15: Fjale Kyce 13 | K15: Lidhja me fushat e tjera 13 | L15: =A15 -> 13 | M15: =B15 -> Lenda1 Tema13 | N15: Organizimi 13 | O15: Detyre shtepie 1: | P15: Kompetenca 13 | Q15: 5
A16: 14 | B16: Lenda1 Tema14 | C16: Detyre shtepie 14 | D16: faqe 14 | E16: Situata 14 | F16: Metodologjia 14 | G16: Vleresimi 14 | H16: Burimi 14 | I16: Rezultati 14 | J16: Fjale Kyce 14 | K16: Lidhja me fushat e tjera 14 | L16: =A16 -> 14 | M16: =B16 -> Lenda1 Tema14 | N16: Organizimi 14 | O16: Detyre shtepie 1: | P16: Kompetenca 14
A17: 15 | B17: Lenda1 Tema15 | C17: Detyre shtepie 15 | D17: faqe 15 | E17: Situata 15 | F17: Metodologjia 15 | G17: Vleresimi 15 | H17: Burimi 15 | I17: Rezultati 15 | J17: Fjale Kyce 15 | K17: Lidhja me fushat e tjera 15 | L17: =A17 -> 15 | M17: =B17 -> Lenda1 Tema15 | N17: Organizimi 15 | O17: Detyre shtepie 1: | P17: Kompetenca 15
A18: 16 | B18: Lenda1 Tema16 | C18: Detyre shtepie 16 | D18: faqe 16 | E18: Situata 16 | F18: Metodologjia 16 | G18: Vleresimi 16 | H18: Burimi 16 | I18: Rezultati 16 | J18: Fjale Kyce 16 | K18: Lidhja me fushat e tjera 16 | L18: =A18 -> 16 | M18: =B18 -> Lenda1 Tema16 | N18: Organizimi 16 | O18: Detyre shtepie 1: | P18: Kompetenca 16 | Q18: 6
A19: 17 | B19: Lenda1 Tema17 | C19: Detyre shtepie 17 | D19: faqe 17 | E19: Situata 17 | F19: Metodologjia 17 | G19: Vleresimi 17 | H19: Burimi 17 | I19: Rezultati 17 | J19: Fjale Kyce 17 | K19: Lidhja me fushat e tjera 17 | L19: =A19 -> 17 | M19: =B19 -> Lenda1 Tema17 | N19: Organizimi 17 | O19: Detyre shtepie 1: | P19: Kompetenca 17
A20: 18 | B20: Lenda1 Tema18 | C20: Detyre shtepie 18 | D20: faqe 18 | E20: Situata 18 | F20: Metodologjia 18 | G20: Vleresimi 18 | H20: Burimi 18 | I20: Rezultati 18 | J20: Fjale Kyce 18 | K20: Lidhja me fushat e tjera 18 | L20: =A20 -> 18 | M20: =B20 -> Lenda1 Tema18 | N20: Organizimi 18 | O20: Detyre shtepie 1: | P20: Kompetenca 18
A21: 19 | B21: Lenda1 Tema19 | C21: Detyre shtepie 19 | D21: faqe 19 | E21: Situata 19 | F21: Metodologjia 19 | G21: Vleresimi 19 | H21: Burimi 19 | I21: Rezultati 19 | J21: Fjale Kyce 19 | K21: Lidhja me fushat e tjera 19 | L21: =A21 -> 19 | M21: =B21 -> Lenda1 Tema19 | N21: Organizimi 19 | O21: Detyre shtepie 1: | P21: Kompetenca 19 | Q21: 7
A22: 20 | B22: Lenda1 Tema20 | C22: Detyre shtepie 20 | D22: faqe 20 | E22: Situata 20 | F22: Metodologjia 20 | G22: Vleresimi 20 | H22: Burimi 20 | I22: Rezultati 20 | J22: Fjale Kyce 20 | K22: Lidhja me fushat e tjera 20 | L22: =A22 -> 20 | M22: =B22 -> Lenda1 Tema20 | N22: Organizimi 20 | O22: Detyre shtepie 1: | P22: Kompetenca 20
A23: 21 | B23: Lenda1 Tema21 | C23: Detyre shtepie 21 | D23: faqe 21 | E23: Situata 21 | F23: Metodologjia 21 | G23: Vleresimi 21 | H23: Burimi 21 | I23: Rezultati 21 | J23: Fjale Kyce 21 | K23: Lidhja me fushat e tjera 21 | L23: =A23 -> 21 | M23: =B23 -> Lenda1 Tema21 | N23: Organizimi 21 | O23: Detyre shtepie 1: | P23: Kompetenca 21
A24: 22 | B24: Lenda1 Tema22 | C24: Detyre shtepie 22 | D24: faqe 22 | E24: Situata 22 | F24: Metodologjia 22 | G24: Vleresimi 22 | H24: Burimi 22 | I24: Rezultati 22 | J24: Fjale Kyce 22 | K24: Lidhja me fushat e tjera 22 | L24: =A24 -> 22 | M24: =B24 -> Lenda1 Tema22 | N24: Organizimi 22 | O24: Detyre shtepie 1: | P24: Kompetenca 22 | Q24: 8
A25: 23 | B25: Lenda1 Tema23 | C25: Detyre shtepie 23 | D25: faqe 23 | E25: Situata 23 | F25: Metodologjia 23 | G25: Vleresimi 23 | H25: Burimi 23 | I25: Rezultati 23 | J25: Fjale Kyce 23 | K25: Lidhja me fushat e tjera 23 | L25: =A25 -> 23 | M25: =B25 -> Lenda1 Tema23 | N25: Organizimi 23 | O25: Detyre shtepie 1: | P25: Kompetenca 23
A26: 24 | B26: Lenda1 Tema24 | C26: Detyre shtepie 24 | D26: faqe 24 | E26: Situata 24 | F26: Metodologjia 24 | G26: Vleresimi 24 | H26: Burimi 24 | I26: Rezultati 24 | J26: Fjale Kyce 24 | K26: Lidhja me fushat e tjera 24 | L26: =A26 -> 24 | M26: =B26 -> Lenda1 Tema24 | N26: Organizimi 24 | O26: Detyre shtepie 1: | P26: Kompetenca 24
A27: 25 | B27: Lenda1 Tema25 | C27: Detyre shtepie 25 | D27: faqe 25 | E27: Situata 25 | F27: Metodologjia 25 | G27: Vleresimi 25 | H27: Burimi 25 | I27: Rezultati 25 | J27: Fjale Kyce 25 | K27: Lidhja me fushat e tjera 25 | L27: =A27 -> 25 | M27: =B27 -> Lenda1 Tema25 | N27: Organizimi 25 | O27: Detyre shtepie 1: | P27: Kompetenca 25 | Q27: 9
A28: 26 | B28: Lenda1 Tema26 | C28: Detyre shtepie 26 | D28: faqe 26 | E28: Situata 26 | F28: Metodologjia 26 | G28: Vleresimi 26 | H28: Burimi 26 | I28: Rezultati 26 | J28: Fjale Kyce 26 | K28: Lidhja me fushat e tjera 26 | L28: =A28 -> 26 | M28: =B28 -> Lenda1 Tema26 | N28: Organizimi 26 | O28: Detyre shtepie 1: | P28: Kompetenca 26
A29: 27 | B29: Lenda1 Tema27 | C29: Detyre shtepie 27 | D29: faqe 27 | E29: Situata 27 | F29: Metodologjia 27 | G29: Vleresimi 27 | H29: Burimi 27 | I29: Rezultati 27 | J29: Fjale Kyce 27 | K29: Lidhja me fushat e tjera 27 | L29: =A29 -> 27 | M29: =B29 -> Lenda1 Tema27 | N29: Organizimi 27 | O29: Detyre shtepie 1: | P29: Kompetenca 27
A30: 28 | B30: Lenda1 Tema28 | C30: Detyre shtepie 28 | D30: faqe 28 | E30: Situata 28 | F30: Metodologjia 28 | G30: Vleresimi 28 | H30: Burimi 28 | I30: Rezultati 28 | J30: Fjale Kyce 28 | K30: Lidhja me fushat e tjera 28 | L30: =A30 -> 28 | M30: =B30 -> Lenda1 Tema28 | N30: Organizimi 28 | O30: Detyre shtepie 1: | P30: Kompetenca 28 | Q30: 10
A31: 29 | B31: Lenda1 Tema29 | C31: Detyre shtepie 29 | D31: faqe 29 | E31: Situata 29 | F31: Metodologjia 29 | G31: Vleresimi 29 | H31: Burimi 29 | I31: Rezultati 29 | J31: Fjale Kyce 29 | K31: Lidhja me fushat e tjera 29 | L31: =A31 -> 29 | M31: =B31 -> Lenda1 Tema29 | N31: Organizimi 29 | O31: Detyre shtepie 1: | P31: Kompetenca 29
A32: 30 | B32: Lenda1 Tema30 | C32: Detyre shtepie 30 | D32: faqe 30 | E32: Situata 30 | F32: Metodologjia 30 | G32: Vleresimi 30 | H32: Burimi 30 | I32: Rezultati 30 | J32: Fjale Kyce 30 | K32: Lidhja me fushat e tjera 30 | L32: =A32 -> 30 | M32: =B32 -> Lenda1 Tema30 | N32: Organizimi 30 | O32: Detyre shtepie 1: | P32: Kompetenca 30
A33: 31 | B33: Lenda1 Tema31 | C33: Detyre shtepie 31 | D33: faqe 31 | E33: Situata 31 | F33: Metodologjia 31 | G33: Vleresimi 31 | H33: Burimi 31 | I33: Rezultati 31 | J33: Fjale Kyce 31 | K33: Lidhja me fushat e tjera 31 | L33: =A33 -> 31 | M33: =B33 -> Lenda1 Tema31 | N33: Organizimi 31 | O33: Detyre shtepie 1: | P33: Kompetenca 31 | Q33: 11
A34: 32 | B34: Lenda1 Tema32 | C34: Detyre shtepie 32 | D34: faqe 32 | E34: Situata 32 | F34: Metodologjia 32 | G34: Vleresimi 32 | H34: Burimi 32 | I34: Rezultati 32 | J34: Fjale Kyce 32 | K34: Lidhja me fushat e tjera 32 | L34: =A34 -> 32 | M34: =B34 -> Lenda1 Tema32 | N34: Organizimi 32 | O34: Detyre shtepie 1: | P34: Kompetenca 32
A35: 33 | B35: Lenda1 Tema33 | C35: Detyre shtepie 33 | D35: faqe 33 | E35: Situata 33 | F35: Metodologjia 33 | G35: Vleresimi 33 | H35: Burimi 33 | I35: Rezultati 33 | J35: Fjale Kyce 33 | K35: Lidhja me fushat e tjera 33 | L35: =A35 -> 33 | M35: =B35 -> Lenda1 Tema33 | N35: Organizimi 33 | O35: Detyre shtepie 1: | P35: Kompetenca 33
A36: 34 | B36: Lenda1 Tema34 | C36: Detyre shtepie 34 | D36: faqe 34 | E36: Situata 34 | F36: Metodologjia 34 | G36: Vleresimi 34 | H36: Burimi 34 | I36: Rezultati 34 | J36: Fjale Kyce 34 | K36: Lidhja me fushat e tjera 34 | L36: =A36 -> 34 | M36: =B36 -> Lenda1 Tema34 | N36: Organizimi 34 | O36: Detyre shtepie 1: | P36: Kompetenca 34 | Q36: 12
A37: 35 | B37: Lenda1 Tema35 | C37: Detyre shtepie 35 | D37: faqe 35 | E37: Situata 35 | F37: Metodologjia 35 | G37: Vleresimi 35 | H37: Burimi 35 | I37: Rezultati 35 | J37: Fjale Kyce 35 | K37: Lidhja me fushat e tjera 35 | L37: =A37 -> 35 | M37: =B37 -> Lenda1 Tema35 | N37: Organizimi 35 | O37: Detyre shtepie 1: | P37: Kompetenca 35
A38: 36 | B38: Lenda1 Tema36 | C38: Detyre shtepie 36 | D38: faqe 36 | E38: Situata 36 | F38: Metodologjia 36 | G38: Vleresimi 36 | H38: Burimi 36 | I38: Rezultati 36 | J38: Fjale Kyce 36 | K38: Lidhja me fushat e tjera 36 | L38: =A38 -> 36 | M38: =B38 -> Lenda1 Tema36 | N38: Organizimi 36 | O38: Detyre shtepie 1: | P38: Kompetenca 36
A39: 37 | B39: Lenda1 Tema37 | C39: Detyre shtepie 37 | D39: faqe 37 | E39: Situata 37 | F39: Metodologjia 37 | G39: Vleresimi 37 | H39: Burimi 37 | I39: Rezultati 37 | J39: Fjale Kyce 37 | K39: Lidhja me fushat e tjera 37 | L39: =A39 -> 37 | M39: =B39 -> Lenda1 Tema37 | N39: Organizimi 37 | O39: Detyre shtepie 1: | P39: Kompetenca 37 | Q39: 13
A40: 38 | B40: Lenda1 Tema38 | C40: Detyre shtepie 38 | D40: faqe 38 | E40: Situata 38 | F40: Metodologjia 38 | G40: Vleresimi 38 | H40: Burimi 38 | I40: Rezultati 38 | J40: Fjale Kyce 38 | K40: Lidhja me fushat e tjera 38 | L40: =A40 -> 38 | M40: =B40 -> Lenda1 Tema38 | N40: Organizimi 38 | O40: Detyre shtepie 1: | P40: Kompetenca 38
...

Sheet JAVA viti IV
A1: 1 | B1: 2 | C1: 3 | D1: 4 | E1: 5 | F1: 6 | G1: 7 | H1: 8 | I1: 9 | J1: 10 | K1: 11 | L1: 12 | M1: 13 | N1: 14 | O1: 15 | P1: 16
A2: Nr | B2: Tema | C2: Detyra Shtepie | D2: Fq Ditari | E2: Situata e të nxënit: | F2: Metodologjia dhe veprimtaritë e nxënësve: | G2: Vlerësimi: | H2: Burimet: | I2: Rezultatet e të nxënit sipas kompetencave kyç: | J2: Fjalët kyç: | K2: Lidhja me fusha të tjera ose me temat ndërkurrikulare: | L2: Nr | M2: Tema | N2: Organizimi i orës së mësimit: | O2: Detyre shtepie: | P2: Kompetencat që përfitojnë: | Q2: Java
A3: 1 | B3: Lenda 2 tema 1 | C3: Detyre shtepie 1 | D3: faqe 1 | E3: Situata 1 | F3: Metodologjia 1 | G3: Vleresimi 1 | H3: Burimi 1 | I3: Rezultati 1 | J3: Fjale Kyce 1 | K3: Lidhja me fushat e tjera 1 | L3: =A3 -> 1 | M3: =B3 -> Lenda 2 tema 1 | N3: Organizimi 1 | O3: Detyre shtepie 1: | P3: Kompetenca 1 | Q3: 1
A4: 2 | B4: Lenda 2 tema 2 | C4: Detyre shtepie 2 | D4: faqe 2 | E4: Situata 2 | F4: Metodologjia 2 | G4: Vleresimi 2 | H4: Burimi 2 | I4: Rezultati 2 | J4: Fjale Kyce 2 | K4: Lidhja me fushat e tjera 2 | L4: =A4 -> 2 | M4: =B4 -> Lenda 2 tema 2 | N4: Organizimi 2 | O4: Detyre shtepie 1: | P4: Kompetenca 2
A5: 3 | B5: Lenda 2 tema 3 | C5: Detyre shtepie 3 | D5: faqe 3 | E5: Situata 3 | F5: Metodologjia 3 | G5: Vleresimi 3 | H5: Burimi 3 | I5: Rezultati 3 | J5: Fjale Kyce 3 | K5: Lidhja me fushat e tjera 3 | L5: =A5 -> 3 | M5: =B5 -> Lenda 2 tema 3 | N5: Organizimi 3 | O5: Detyre shtepie 1: | P5: Kompetenca 3
A6: 4 | B6: Lenda 2 tema 4 | C6: Detyre shtepie 4 | D6: faqe 4 | E6: Situata 4 | F6: Metodologjia 4 | G6: Vleresimi 4 | H6: Burimi 4 | I6: Rezultati 4 | J6: Fjale Kyce 4 | K6: Lidhja me fushat e tjera 4 | L6: =A6 -> 4 | M6: =B6 -> Lenda 2 tema 4 | N6: Organizimi 4 | O6: Detyre shtepie 1: | P6: Kompetenca 4 | Q6: 2
A7: 5 | B7: Lenda 2 tema 5 | C7: Detyre shtepie 5 | D7: faqe 5 | E7: Situata 5 | F7: Metodologjia 5 | G7: Vleresimi 5 | H7: Burimi 5 | I7: Rezultati 5 | J7: Fjale Kyce 5 | K7: Lidhja me fushat e tjera 5 | L7: =A7 -> 5 | M7: =B7 -> Lenda 2 tema 5 | N7: Organizimi 5 | O7: Detyre shtepie 1: | P7: Kompetenca 5
A8: 6 | B8: Lenda 2 tema 6 | C8: Detyre shtepie 6 | D8: faqe 6 | E8: Situata 6 | F8: Metodologjia 6 | G8: Vleresimi 6 | H8: Burimi 6 | I8: Rezultati 6 | J8: Fjale Kyce 6 | K8: Lidhja me fushat e tjera 6 | L8: =A8 -> 6 | M8: =B8 -> Lenda 2 tema 6 | N8: Organizimi 6 | O8: Detyre shtepie 1: | P8: Kompetenca 6
A9: 7 | B9: Lenda 2 tema 7 | C9: Detyre shtepie 7 | D9: faqe 7 | E9: Situata 7 | F9: Metodologjia 7 | G9: Vleresimi 7 | H9: Burimi 7 | I9: Rezultati 7 | J9: Fjale Kyce 7 | K9: Lidhja me fushat e tjera 7 | L9: =A9 -> 7 | M9: =B9 -> Lenda 2 tema 7 | N9: Organizimi 7 | O9: Detyre shtepie 1: | P9: Kompetenca 7 | Q9: 3
A10: 8 | B10: Lenda 2 tema 8 | C10: Detyre shtepie 8 | D10: faqe 8 | E10: Situata 8 | F10: Metodologjia 8 | G10: Vleresimi 8 | H10: Burimi 8 | I10: Rezultati 8 | J10: Fjale Kyce 8 | K10: Lidhja me fushat e tjera 8 | L10: =A10 -> 8 | M10: =B10 -> Lenda 2 tema 8 | N10: Organizimi 8 | O10: Detyre shtepie 1: | P10: Kompetenca 8
A11: 9 | B11: Lenda 2 tema 9 | C11: Detyre shtepie 9 | D11: faqe 9 | E11: Situata 9 | F11: Metodologjia 9 | G11: Vleresimi 9 | H11: Burimi 9 | I11: Rezultati 9 | J11: Fjale Kyce 9 | K11: Lidhja me fushat e tjera 9 | L11: =A11 -> 9 | M11: =B11 -> Lenda 2 tema 9 | N11: Organizimi 9 | O11: Detyre shtepie 1: | P11: Kompetenca 9
A12: 10 | B12: Lenda 2 tema 10 | C12: Detyre shtepie 10 | D12: faqe 10 | E12: Situata 10 | F12: Metodologjia 10 | G12: Vleresimi 10 | H12: Burimi 10 | I12: Rezultati 10 | J12: Fjale Kyce 10 | K12: Lidhja me fushat e tjera 10 | L12: =A12 -> 10 | M12: =B12 -> Lenda 2 tema 10 | N12: Organizimi 10 | O12: Detyre shtepie 1: | P12: Kompetenca 10 | Q12: 4
A13: 11 | B13: Lenda 2 tema 11 | C13: Detyre shtepie 11 | D13: faqe 11 | E13: Situata 11 | F13: Metodologjia 11 | G13: Vleresimi 11 | H13: Burimi 11 | I13: Rezultati 11 | J13: Fjale Kyce 11 | K13: Lidhja me fushat e tjera 11 | L13: =A13 -> 11 | M13: =B13 -> Lenda 2 tema 11 | N13: Organizimi 11 | O13: Detyre shtepie 1: | P13: Kompetenca 11
A14: 12 | B14: Lenda 2 tema 12 | C14: Detyre shtepie 12 | D14: faqe 12 | E14: Situata 12 | F14: Metodologjia 12 | G14: Vleresimi 12 | H14: Burimi 12 | I14: Rezultati 12 | J14: Fjale Kyce 12 | K14: Lidhja me fushat e tjera 12 | L14: =A14 -> 12 | M14: =B14 -> Lenda 2 tema 12 | N14: Organizimi 12 | O14: Detyre shtepie 1: | P14: Kompetenca 12
A15: 13 | B15: Lenda 2 tema 13 | C15: Detyre shtepie 13 | D15: faqe 13 | E15: Situata 13 | F15: Metodologjia 13 | G15: Vleresimi 13 | H15: Burimi 13 | I15: Rezultati 13 | J15: Fjale Kyce 13 | K15: Lidhja me fushat e tjera 13 | L15: =A15 -> 13 | M15: =B15 -> Lenda 2 tema 13 | N15: Organizimi 13 | O15: Detyre shtepie 1: | P15: Kompetenca 13 | Q15: 5
A16: 14 | B16: Lenda 2 tema 14 | C16: Detyre shtepie 14 | D16: faqe 14 | E16: Situata 14 | F16: Metodologjia 14 | G16: Vleresimi 14 | H16: Burimi 14 | I16: Rezultati 14 | J16: Fjale Kyce 14 | K16: Lidhja me fushat e tjera 14 | L16: =A16 -> 14 | M16: =B16 -> Lenda 2 tema 14 | N16: Organizimi 14 | O16: Detyre shtepie 1: | P16: Kompetenca 14
A17: 15 | B17: Lenda 2 tema 15 | C17: Detyre shtepie 15 | D17: faqe 15 | E17: Situata 15 | F17: Metodologjia 15 | G17: Vleresimi 15 | H17: Burimi 15 | I17: Rezultati 15 | J17: Fjale Kyce 15 | K17: Lidhja me fushat e tjera 15 | L17: =A17 -> 15 | M17: =B17 -> Lenda 2 tema 15 | N17: Organizimi 15 | O17: Detyre shtepie 1: | P17: Kompetenca 15
A18: 16 | B18: Lenda 2 tema 16 | C18: Detyre shtepie 16 | D18: faqe 16 | E18: Situata 16 | F18: Metodologjia 16 | G18: Vleresimi 16 | H18: Burimi 16 | I18: Rezultati 16 | J18: Fjale Kyce 16 | K18: Lidhja me fushat e tjera 16 | L18: =A18 -> 16 | M18: =B18 -> Lenda 2 tema 16 | N18: Organizimi 16 | O18: Detyre shtepie 1: | P18: Kompetenca 16 | Q18: 6
A19: 17 | B19: Lenda 2 tema 17 | C19: Detyre shtepie 17 | D19: faqe 17 | E19: Situata 17 | F19: Metodologjia 17 | G19: Vleresimi 17 | H19: Burimi 17 | I19: Rezultati 17 | J19: Fjale Kyce 17 | K19: Lidhja me fushat e tjera 17 | L19: =A19 -> 17 | M19: =B19 -> Lenda 2 tema 17 | N19: Organizimi 17 | O19: Detyre shtepie 1: | P19: Kompetenca 17
A20: 18 | B20: Lenda 2 tema 18 | C20: Detyre shtepie 18 | D20: faqe 18 | E20: Situata 18 | F20: Metodologjia 18 | G20: Vleresimi 18 | H20: Burimi 18 | I20: Rezultati 18 | J20: Fjale Kyce 18 | K20: Lidhja me fushat e tjera 18 | L20: =A20 -> 18 | M20: =B20 -> Lenda 2 tema 18 | N20: Organizimi 18 | O20: Detyre shtepie 1: | P20: Kompetenca 18
A21: 19 | B21: Lenda 2 tema 19 | C21: Detyre shtepie 19 | D21: faqe 19 | E21: Situata 19 | F21: Metodologjia 19 | G21: Vleresimi 19 | H21: Burimi 19 | I21: Rezultati 19 | J21: Fjale Kyce 19 | K21: Lidhja me fushat e tjera 19 | L21: =A21 -> 19 | M21: =B21 -> Lenda 2 tema 19 | N21: Organizimi 19 | O21: Detyre shtepie 1: | P21: Kompetenca 19 | Q21: 7
A22: 20 | B22: Lenda 2 tema 20 | C22: Detyre shtepie 20 | D22: faqe 20 | E22: Situata 20 | F22: Metodologjia 20 | G22: Vleresimi 20 | H22: Burimi 20 | I22: Rezultati 20 | J22: Fjale Kyce 20 | K22: Lidhja me fushat e tjera 20 | L22: =A22 -> 20 | M22: =B22 -> Lenda 2 tema 20 | N22: Organizimi 20 | O22: Detyre shtepie 1: | P22: Kompetenca 20
A23: 21 | B23: Lenda 2 tema 21 | C23: Detyre shtepie 21 | D23: faqe 21 | E23: Situata 21 | F23: Metodologjia 21 | G23: Vleresimi 21 | H23: Burimi 21 | I23: Rezultati 21 | J23: Fjale Kyce 21 | K23: Lidhja me fushat e tjera 21 | L23: =A23 -> 21 | M23: =B23 -> Lenda 2 tema 21 | N23: Organizimi 21 | O23: Detyre shtepie 1: | P23: Kompetenca 21
A24: 22 | B24: Lenda 2 tema 22 | C24: Detyre shtepie 22 | D24: faqe 22 | E24: Situata 22 | F24: Metodologjia 22 | G24: Vleresimi 22 | H24: Burimi 22 | I24: Rezultati 22 | J24: Fjale Kyce 22 | K24: Lidhja me fushat e tjera 22 | L24: =A24 -> 22 | M24: =B24 -> Lenda 2 tema 22 | N24: Organizimi 22 | O24: Detyre shtepie 1: | P24: Kompetenca 22 | Q24: 8
A25: 23 | B25: Lenda 2 tema 23 | C25: Detyre shtepie 23 | D25: faqe 23 | E25: Situata 23 | F25: Metodologjia 23 | G25: Vleresimi 23 | H25: Burimi 23 | I25: Rezultati 23 | J25: Fjale Kyce 23 | K25: Lidhja me fushat e tjera 23 | L25: =A25 -> 23 | M25: =B25 -> Lenda 2 tema 23 | N25: Organizimi 23 | O25: Detyre shtepie 1: | P25: Kompetenca 23
A26: 24 | B26: Lenda 2 tema 24 | C26: Detyre shtepie 24 | D26: faqe 24 | E26: Situata 24 | F26: Metodologjia 24 | G26: Vleresimi 24 | H26: Burimi 24 | I26: Rezultati 24 | J26: Fjale Kyce 24 | K26: Lidhja me fushat e tjera 24 | L26: =A26 -> 24 | M26: =B26 -> Lenda 2 tema 24 | N26: Organizimi 24 | O26: Detyre shtepie 1: | P26: Kompetenca 24
A27: 25 | B27: Lenda 2 tema 25 | C27: Detyre shtepie 25 | D27: faqe 25 | E27: Situata 25 | F27: Metodologjia 25 | G27: Vleresimi 25 | H27: Burimi 25 | I27: Rezultati 25 | J27: Fjale Kyce 25 | K27: Lidhja me fushat e tjera 25 | L27: =A27 -> 25 | M27: =B27 -> Lenda 2 tema 25 | N27: Organizimi 25 | O27: Detyre shtepie 1: | P27: Kompetenca 25 | Q27: 9
A28: 26 | B28: Lenda 2 tema 26 | C28: Detyre shtepie 26 | D28: faqe 26 | E28: Situata 26 | F28: Metodologjia 26 | G28: Vleresimi 26 | H28: Burimi 26 | I28: Rezultati 26 | J28: Fjale Kyce 26 | K28: Lidhja me fushat e tjera 26 | L28: =A28 -> 26 | M28: =B28 -> Lenda 2 tema 26 | N28: Organizimi 26 | O28: Detyre shtepie 1: | P28: Kompetenca 26
A29: 27 | B29: Lenda 2 tema 27 | C29: Detyre shtepie 27 | D29: faqe 27 | E29: Situata 27 | F29: Metodologjia 27 | G29: Vleresimi 27 | H29: Burimi 27 | I29: Rezultati 27 | J29: Fjale Kyce 27 | K29: Lidhja me fushat e tjera 27 | L29: =A29 -> 27 | M29: =B29 -> Lenda 2 tema 27 | N29: Organizimi 27 | O29: Detyre shtepie 1: | P29: Kompetenca 27
A30: 28 | B30: Lenda 2 tema 28 | C30: Detyre shtepie 28 | D30: faqe 28 | E30: Situata 28 | F30: Metodologjia 28 | G30: Vleresimi 28 | H30: Burimi 28 | I30: Rezultati 28 | J30: Fjale Kyce 28 | K30: Lidhja me fushat e tjera 28 | L30: =A30 -> 28 | M30: =B30 -> Lenda 2 tema 28 | N30: Organizimi 28 | O30: Detyre shtepie 1: | P30: Kompetenca 28 | Q30: 10
A31: 29 | B31: Lenda 2 tema 29 | C31: Detyre shtepie 29 | D31: faqe 29 | E31: Situata 29 | F31: Metodologjia 29 | G31: Vleresimi 29 | H31: Burimi 29 | I31: Rezultati 29 | J31: Fjale Kyce 29 | K31: Lidhja me fushat e tjera 29 | L31: =A31 -> 29 | M31: =B31 -> Lenda 2 tema 29 | N31: Organizimi 29 | O31: Detyre shtepie 1: | P31: Kompetenca 29
A32: 30 | B32: Lenda 2 tema 30 | C32: Detyre shtepie 30 | D32: faqe 30 | E32: Situata 30 | F32: Metodologjia 30 | G32: Vleresimi 30 | H32: Burimi 30 | I32: Rezultati 30 | J32: Fjale Kyce 30 | K32: Lidhja me fushat e tjera 30 | L32: =A32 -> 30 | M32: =B32 -> Lenda 2 tema 30 | N32: Organizimi 30 | O32: Detyre shtepie 1: | P32: Kompetenca 30
A33: 31 | B33: Lenda 2 tema 31 | C33: Detyre shtepie 31 | D33: faqe 31 | E33: Situata 31 | F33: Metodologjia 31 | G33: Vleresimi 31 | H33: Burimi 31 | I33: Rezultati 31 | J33: Fjale Kyce 31 | K33: Lidhja me fushat e tjera 31 | L33: =A33 -> 31 | M33: =B33 -> Lenda 2 tema 31 | N33: Organizimi 31 | O33: Detyre shtepie 1: | P33: Kompetenca 31 | Q33: 11
A34: 32 | B34: Lenda 2 tema 32 | C34: Detyre shtepie 32 | D34: faqe 32 | E34: Situata 32 | F34: Metodologjia 32 | G34: Vleresimi 32 | H34: Burimi 32 | I34: Rezultati 32 | J34: Fjale Kyce 32 | K34: Lidhja me fushat e tjera 32 | L34: =A34 -> 32 | M34: =B34 -> Lenda 2 tema 32 | N34: Organizimi 32 | O34: Detyre shtepie 1: | P34: Kompetenca 32
A35: 33 | B35: Lenda 2 tema 33 | C35: Detyre shtepie 33 | D35: faqe 33 | E35: Situata 33 | F35: Metodologjia 33 | G35: Vleresimi 33 | H35: Burimi 33 | I35: Rezultati 33 | J35: Fjale Kyce 33 | K35: Lidhja me fushat e tjera 33 | L35: =A35 -> 33 | M35: =B35 -> Lenda 2 tema 33 | N35: Organizimi 33 | O35: Detyre shtepie 1: | P35: Kompetenca 33
A36: 34 | B36: Lenda 2 tema 34 | C36: Detyre shtepie 34 | D36: faqe 34 | E36: Situata 34 | F36: Metodologjia 34 | G36: Vleresimi 34 | H36: Burimi 34 | I36: Rezultati 34 | J36: Fjale Kyce 34 | K36: Lidhja me fushat e tjera 34 | L36: =A36 -> 34 | M36: =B36 -> Lenda 2 tema 34 | N36: Organizimi 34 | O36: Detyre shtepie 1: | P36: Kompetenca 34 | Q36: 12
A37: 35 | B37: Lenda 2 tema 35 | C37: Detyre shtepie 35 | D37: faqe 35 | E37: Situata 35 | F37: Metodologjia 35 | G37: Vleresimi 35 | H37: Burimi 35 | I37: Rezultati 35 | J37: Fjale Kyce 35 | K37: Lidhja me fushat e tjera 35 | L37: =A37 -> 35 | M37: =B37 -> Lenda 2 tema 35 | N37: Organizimi 35 | O37: Detyre shtepie 1: | P37: Kompetenca 35
A38: 36 | B38: Lenda 2 tema 36 | C38: Detyre shtepie 36 | D38: faqe 36 | E38: Situata 36 | F38: Metodologjia 36 | G38: Vleresimi 36 | H38: Burimi 36 | I38: Rezultati 36 | J38: Fjale Kyce 36 | K38: Lidhja me fushat e tjera 36 | L38: =A38 -> 36 | M38: =B38 -> Lenda 2 tema 36 | N38: Organizimi 36 | O38: Detyre shtepie 1: | P38: Kompetenca 36
A39: 37 | B39: Lenda 2 tema 37 | C39: Detyre shtepie 37 | D39: faqe 37 | E39: Situata 37 | F39: Metodologjia 37 | G39: Vleresimi 37 | H39: Burimi 37 | I39: Rezultati 37 | J39: Fjale Kyce 37 | K39: Lidhja me fushat e tjera 37 | L39: =A39 -> 37 | M39: =B39 -> Lenda 2 tema 37 | N39: Organizimi 37 | O39: Detyre shtepie 1: | P39: Kompetenca 37 | Q39: 13
A40: 38 | B40: Lenda 2 tema 38 | C40: Detyre shtepie 38 | D40: faqe 38 | E40: Situata 38 | F40: Metodologjia 38 | G40: Vleresimi 38 | H40: Burimi 38 | I40: Rezultati 38 | J40: Fjale Kyce 38 | K40: Lidhja me fushat e tjera 38 | L40: =A40 -> 38 | M40: =B40 -> Lenda 2 tema 38 | N40: Organizimi 38 | O40: Detyre shtepie 1: | P40: Kompetenca 38
...

Sheet Oret pushim 
A7: Klasa | B7: III3 | C7: III4 | D7: III5 | E7: III6 | F7: III7 | G7: III8 | H7: IV6 | I7: IV7 | J7: III8 | K7: Data | L7: Java
A8: Ore mbrapa | B8: =SUM(B12:B31) -> 0 | C8: =SUM(C12:C31) -> 0 | D8: =SUM(D12:D31) -> 0 | E8: =SUM(E12:E31) -> 0 | F8: =SUM(F12:F31) -> 0 | G8: =SUM(G12:G31) -> 0 | H8: =SUM(H12:H31) -> 0 | I8: =SUM(I12:I31) -> 0 | J8: =SUM(J12:J31) -> 0 | K8: 45908 | L8: 1
K9: 45909
K10: 45910
A11: Pushimet: | K11: 45911
A12: Dita e pare kujdestari | K12: 45912
K13: 45913
K14: 45914
K15: 45915 | L15: 2
K16: 45916
K17: 45917
K18: 45918
K19: 45919
K20: 45920
K21: 45921
K22: 45922 | L22: 3
K23: 45923
K24: 45924
K25: 45925
K26: 45926
K27: 45927
K28: 45928
K29: 45929 | L29: 4
K30: 45930
K31: 45931
K32: 45932
A33: ORARI I MESIMEVE | K33: 45933
A34: Ditet Oret | B34: E HENE | C34: E MARTE | D34: E MERKURE | E34: E ENJTE | F34: E PREMTE | K34: 45934
A35: 1 - 08:00 - 08:45 | K35: 45935
A36: 2 - 08:50 - 09:35 | D36: C++ 3-3 | E36: C++ 3-7 | K36: 45936 | L36: 5
A37: 3 - 09:40 - 10:25 | D37: JAVA 4-7 | E37: C++ 3-3 | F37: C++ 3-6 | K37: 45937
A38: 4 - 10:50 - 11:35 | C38: C++ 3-5 | D38: JAVA 4-7 | E38: C++ 3-3 | F38: C++ 3-6 | K38: 45938
A39: 5 - 11:40 - 12:25 | B39: C++ 3-6 | C39: C++ 3-5 | D39: C++ 3-8 | E39: C++ 3-4 | F39: C++ 3-5 | K39: 45939
A40: 6 - 12:30 - 13:15 | B40: JAVA 4-7 | C40: C++ 3-7 | D40: C++ 3-8 | E40: C++ 3-4 | F40: C++ 3-8 | K40: 45940
A41: 7 - 13:20 - 14:05 | B41: C++ 3-4 | C41: C++ 3-7 | K41: 45941
K42: 45942
K43: 45943 | L43: 6
K44: 45944
K45: 45945
K46: 45946
...

Sheet Ditari javor
A1: JAVA | B1: =VLOOKUP(E1,'Oret pushim '!K8:L294,2,FALSE) -> 8 | C1: E HENE | E1: 45957
A2: ora 1, 2, 3, 4 pushim
A3: Klasa | C3: III6 ora 5
A4: Tema | B4: =(B1-1)*3+1-'Oret pushim '!E8 -> 22 | C4: =VLOOKUP(B4,'C++ viti III'!A2:C110,2,FALSE) -> Lenda1 Tema22
C5: Shih permbajtjen bashkengjitur
A6: Klasa | C6: IV7 ora 6
A7: Tema | B7: =(B1-1)*3+1-'Oret pushim '!I8 -> 22 | C7: =VLOOKUP(B7,'JAVA viti IV'!A3:D126,2,FALSE) -> Lenda 2 tema 22
C8: Shih permbajtjen bashkengjitur
A9: Klasa | C9: III4 ora 7
A10: Tema | B10: =(B1-1)*3+1-'Oret pushim '!C8 -> 22 | C10: =VLOOKUP(B10,'C++ viti III'!A2:C110,2,FALSE) -> Lenda1 Tema22
C11: Shih permbajtjen bashkengjitur
C13: E MARTE | E13: =E1+1 -> 45958
A14: ora 1, 2 ,3 pushim
A15: Klasa | C15: III5 ora 4+5
A16: Tema | B16: =(B1-1)*3+1-'Oret pushim '!D8 -> 22 | C16: =VLOOKUP(B16,'C++ viti III'!A3:C110,2,FALSE) -> Lenda1 Tema22
C17: Shih permbajtjen e klases: | D17: III6 dt: | E17: =$E$1 -> 45957
A18: Tema | B18: =B16+1 -> 23 | C18: =VLOOKUP(B18,'C++ viti III'!A3:C110,2,FALSE) -> Lenda1 Tema23
C19: Shih permbajtjen bashkengjitur
A20: Klasa | C20: III7 ora 6+7
A21: Tema | B21: =(B1-1)*3+1-'Oret pushim '!F8 -> 22 | C21: =VLOOKUP(B21,'C++ viti III'!A2:C110,2,FALSE) -> Lenda1 Tema22
C22: Shih permbajtjen e klases: | D22: III6 dt: | E22: =$E$1 -> 45957
A23: Tema | B23: =B21+1 -> 23 | C23: =VLOOKUP(B23,'C++ viti III'!A2:C110,2,FALSE) -> Lenda1 Tema23
C24: Shih permbajtjen bashkengjitur
C26: E MERKURE | E26: =E1+2 -> 45959
A27: ora 1 pushim
A28: Klasa | C28: III3 ora 2
A29: Tema | B29: =(B1-1)*3+1-'Oret pushim '!B8 -> 22 | C29: =VLOOKUP(B29,'C++ viti III'!A2:C110,2,FALSE) -> Lenda1 Tema22
C30: Shih permbajtjen e klases: | D30: =$D$22 -> III6 dt: | E30: =$E$22 -> 45957
A31: Klasa | C31: IV7 ora 3+4
A32: Tema | B32: =B7+1 -> 23 | C32: =VLOOKUP(B32,'JAVA viti IV'!A3:D126,2,FALSE) -> Lenda 2 tema 23
C33: Shih permbajtjen bashkengjitur
A34: Tema | B34: =B32+1 -> 24 | C34: =VLOOKUP(B34,'JAVA viti IV'!A3:D126,2,FALSE) -> Lenda 2 tema 24
C35: Shih permbajtjen bashkengjitur
A36: Klasa | C36: III8 ora 5+6
A37: Tema | B37: =(B1-1)*3+1-'Oret pushim '!G8 -> 22 | C37: =VLOOKUP(B37,'C++ viti III'!A2:C110,2,FALSE) -> Lenda1 Tema22
C38: Shih permbajtjen e klases: | D38: =$D$22 -> III6 dt: | E38: =$E$22 -> 45957
A39: Tema | B39: =B37+1 -> 23 | C39: =VLOOKUP(B39,'C++ viti III'!A2:C110,2,FALSE) -> Lenda1 Tema23
C40: Shih permbajtjen e klases: | D40: III5 dt: | E40: =$E$13 -> 45958
A41: ora 7 pushim
C43: E ENJTE | E43: =E1+3 -> 45960
...

Sheet Ditari C++
A1: Fusha: | B1: Programim | C1: Lënda: | D1: C++ | E1: Shkalla: V | F1: Klasa | G1: III
A2: Tema mësimore: | C2: 15 | E2: Situata e të nxënit:
A3: =VLOOKUP(C2,'C++ viti III'!A2:P110,2,FALSE) -> Lenda1 Tema15 | E3: =VLOOKUP(C2,'C++ viti III'!A2:P110,5,FALSE) -> Situata 15
A4: Rezultatet e të nxënit sipas kompetencave kyç: | E4: Fjalët kyç: | F4: =VLOOKUP(C2,'C++ viti III'!A2:P110,10,FALSE) -> Fjale Kyce 15
A5: =VLOOKUP(C2,'C++ viti III'!A2:P110,9,FALSE) -> Rezultati 15 | E5: Lidhja me fusha të tjera ose me temat ndërkurrikulare:
E6: =VLOOKUP(C2,'C++ viti III'!A2:P110,11,FALSE) -> Lidhja me fushat e tjera 15
A7: Burimet: | E7: Metodologjia dhe veprimtaritë e nxënësve:
A8: =VLOOKUP(C2,'C++ viti III'!A2:P110,8,FALSE) -> Burimi 15 | E8: =VLOOKUP(C2,'C++ viti III'!A2:P110,6,FALSE) -> Metodologjia 15
A9: Organizimi i orës së mësimit:
A10: =VLOOKUP(C2,'C++ viti III'!A2:P110,14,FALSE) -> Organizimi 15
A11: Kompetencat që përfitojnë: | D11: =VLOOKUP(C2,'C++ viti III'!A2:P110,16,FALSE) -> Kompetenca 15
A12: Vlerësimi: | C12: =VLOOKUP(C2,'C++ viti III'!A2:P110,7,FALSE) -> Vleresimi 15
A13: Detyrat dhe puna e pavarur: | F13: Detyre shtepie:
A14: =VLOOKUP(C2,'C++ viti III'!A2:P110,15,FALSE) -> Detyre shtepie 1: | F14: =VLOOKUP(C2,'C++ viti III'!A2:P110,3,FALSE) -> Detyre shtepie 15

Sheet Ditari JAVA
A1: Fusha: | B1: Programim | C1: Lënda: | D1: JAVA | E1: Shkalla: V | F1: Klasa | G1: IV
A2: Tema mësimore: | C2: 44 | E2: Situata e të nxënit:
A3: =VLOOKUP(C2,'JAVA viti IV'!A3:P126,2,FALSE) -> Lenda 2 tema 44 | E3: =VLOOKUP(C2,'JAVA viti IV'!A3:P126,5,FALSE) -> Situata 44
A4: Rezultatet e të nxënit sipas kompetencave kyç: | E4: Fjalët kyç: | F4: =VLOOKUP(C2,'JAVA viti IV'!A3:P126,10,FALSE) -> Fjale Kyce 44
A5: =VLOOKUP(C2,'JAVA viti IV'!A3:P126,9,FALSE) -> Rezultati 44 | E5: Lidhja me fusha të tjera ose me temat ndërkurrikulare:
E6: =VLOOKUP(C2,'JAVA viti IV'!A3:P126,11,FALSE) -> Lidhja me fushat e tjera 44
A7: Burimet: | E7: Metodologjia dhe veprimtaritë e nxënësve:
A8: =VLOOKUP(C2,'JAVA viti IV'!A3:P126,8,FALSE) -> Burimi 44 | E8: =VLOOKUP(C2,'JAVA viti IV'!A3:P126,6,FALSE) -> Metodologjia 44
A9: Organizimi i orës së mësimit:
A10: =VLOOKUP(C2,'JAVA viti IV'!A3:P126,14,FALSE) -> Organizimi 44
A11: Kompetencat që përfitojnë: | D11: =VLOOKUP(C2,'JAVA viti IV'!A3:P126,16,FALSE) -> Kompetenca 44
A12: Vlerësimi: | C12: =VLOOKUP(C2,'JAVA viti IV'!A3:P126,7,FALSE) -> Vleresimi 44
A13: Detyrat dhe puna e pavarur: | F13: Detyre shtepie:
A14: =VLOOKUP(C2,'JAVA viti IV'!A3:P126,15,FALSE) -> Detyre shtepie 1: | F14: =VLOOKUP(C2,'JAVA viti IV'!A3:P126,3,FALSE) -> Detyre shtepie 44
